<?xml version="1.0" ?>

<robot xmlns:xacro="http://www.ros.org/wiki/xacro"
       xmlns:controller="http://playerstage.sourceforge.net/gazebo/xmlschema/#controller"
    name="inverse_pendulum">

    <!-- includes -->
    <xacro:include filename="$(find inverse_pendulum)/urdf/macros.xacro" />

    <!-- colors -->
    <gazebo reference="base">
        <material>Gazebo/Red</material>
    </gazebo>

    <gazebo reference="foundation">
        <material>Gazebo/Blue</material>
    </gazebo>

    <gazebo reference="connector">
        <material>Gazebo/Yellow</material>
    </gazebo>

    <gazebo reference="arm">
        <material>Gazebo/Green</material>
    </gazebo>

    <!-- ros_control plugin -->
    <gazebo>
        <plugin name="gazebo_ros_control" filename="libgazebo_ros_control.so">
            <robotNamespace>/inverse_pendulum</robotNamespace>
            <legacyModeNS>true</legacyModeNS>
        </plugin>
    </gazebo>

    <!-- object properties -->
    <!-- x-red, y-green, z-blue -->
    <xacro:property name="foundation_width" value="0.5" />
    <xacro:property name="foundation_depth" value="4.0" />
    <xacro:property name="foundation_height" value="1.0" />
    <xacro:property name="foundation_mass" value="" />

    <link name="base">
        <visual>
            <geometry>
                <!-- x-red, y-green, z-blue -->
                <box size="4 4 0.1" />
            </geometry>
            <origin rpy="0 0 0" xyz="0 0 0.05" />
        </visual>
        <collision>
            <geometry>
                <box size="4 4 0.1" />
            </geometry>
            <origin rpy="0 0 0" xyz="0 0 0" />
        </collision>
        <inertial>
            <pose>0 0 0 0 0 0</pose>
            <inertia
                ixx="0.01"
                ixy="0.0"
                ixz="0.0"
                iyy="0.01"
                iyz="0.0"
                izz="0.1" />
            <mass value="10.0" />
        </inertial>
    </link>


    <joint name="base_to_foundation" type="fixed">
        <parent link="base" />
        <child link="foundation" />
        <origin rpy="0 0 0" xyz="0 0 0.15" />
    </joint>

    <link name="foundation">
        <visual>
            <geometry>
                <!-- x-red, y-green, z-blue -->
                <box size="${foundation_width}
                           ${foundation_depth}
                           ${foundation_height}" />
            </geometry>
            <origin rpy="0 0 0" xyz="0 0 0.6" />
            <material name="blue">
                <color rgba="0 0 1 1" />
            </material>
        </visual>
        <collision>
            <geometry>
                <box size="${foundation_width}
                           ${foundation_depth}
                           ${foundation_height}" />
            </geometry>
            <origin rpy="0 0 0" xyz="0 0 0.6" />
        </collision>
        <xacro:inertial_matrix mass="10" />
    </link>

    <joint name="foundation_to_connector" type="prismatic">
        <parent link="foundation" />
        <child link="connector" />
        <origin rpy="0 0 0" xyz="0 0 1.2" />
        <limit upper="1.80" lower="-1.80" effort="100" velocity="100" />
        <axis xyz="0 1 0" />
    </joint>

    <link name="connector">
        <visual>
            <geometry>
                <box size="0.2 0.2 0.2" />
            </geometry>
            <origin rpy="0 0 0" xyz="0 0 0" />
            <material name="yellow">
                <color rgba="1 1 0 1" />
            </material>
        </visual>
        <collision>
            <!-- TODO: Tune this to more realistic values -->
            <geometry>
                <box size="0.2 0.2 0.2" />
            </geometry>
            <origin rpy="0 0 0" xyz="0 0 0" />
        </collision>
        <xacro:inertial_matrix mass="1" />
    </link>

    <joint name="connector_to_arm" type="revolute">
        <parent link="connector" />
        <child link="arm" />
        <!--
        <origin rpy="-${90 * 3.14 / 180} 0 0" xyz="0 0 0.2"/>
        -->
        <origin rpy="0 0 0" xyz="0 0 0.2" />
        <limit upper="${3.14/2}" lower="${-3.14/2}"
            effort="100" velocity="100" />
        <axis xyz="1 0 0" />
        <!-- Determine how these are calculated! -->
        <dynamics damping="0.5" friction="0.2" />
    </joint>

    <link name="arm">
        <visual>
            <geometry>
                <box size="0.2 0.2 2.5" />
            </geometry>
            <origin rpy="0 0 0" xyz="0 0 1.3" />
            <material name="green">
                <color rgba="0 1 0 1" />
            </material>
        </visual>
        <collision>
            <geometry>
                <box size="0.2 0.2 2.5" />
            </geometry>
            <origin rpy="0 0 0" xyz="0 0 1.3" />
        </collision>
        <xacro:inertial_matrix mass="200"/>
    </link>

    <!-- transmissions -->
    <xacro:transmission_block joint_name="foundation_to_connector" />
    <xacro:transmission_block joint_name="connector_to_arm" />


</robot>

