<?xml version="1.0" ?>

<robot xmlns:xacro="http://www.ros.org/wiki/xacro"
       xmlns:controller="http://playerstage.sourceforge.net/gazebo/xmlschema/#controller"
       xmlns:interface="http://playerstage.sourceforge.net/gazebo/xmlschema/#interface"
    name="inverse_pendulum_model">

    <!-- includes -->
    <xacro:include filename="$(find inverse_pendulum_model)/urdf/macros.xacro" />
    <xacro:include filename="$(find inverse_pendulum_model)/urdf/properties.xacro" />

    <!-- colors -->
    <gazebo reference="foot">
        <material>Gazebo/Red</material>
    </gazebo>

    <gazebo reference="foundation">
        <material>Gazebo/Blue</material>
    </gazebo>

    <gazebo reference="connector">
        <material>Gazebo/Yellow</material>
    </gazebo>

    <gazebo reference="arm">
        <material>Gazebo/Green</material>
    </gazebo>

    <!-- ros_control plugin -->
    <gazebo>
        <plugin name="gazebo_ros_control" filename="libgazebo_ros_control.so">
            <robotNamespace>/inverse_pendulum_control</robotNamespace>
            <legacyModeNS>true</legacyModeNS>
        </plugin>
    </gazebo>

    <link name="root">
        <visual>
            <geometry>
                <!-- x-red, y-green, z-blue -->
                <box size="0.1 0.1 0.1" />
            </geometry>
            <origin rpy="0 0 0" xyz="0 0 0" />
        </visual>
    </link>

    <joint name="root_to_foot" type="fixed">
        <parent link="root" />
        <child link="foot" />
        <origin rpy="0 0 0" xyz="0 0 0" />
    </joint>

    <link name="foot">
        <visual>
            <geometry>
                <!-- x-red, y-green, z-blue -->
                <box size="${foot_width} ${foot_depth} ${foot_height}" />
            </geometry>
            <origin rpy="0 0 0" xyz="0 0 0" />
        </visual>
        <collision>
            <geometry>
                <box size="${foot_width} ${foot_depth} ${foot_height}" />
            </geometry>
            <origin rpy="0 0 0" xyz="0 0 0" />
        </collision>
        <xacro:inertial_matrix
            mass="${foot_mass}"
            x_length="${foot_width}"
            y_length="${foot_depth}"
            z_length="${foot_height}"
        />
    </link>

    <joint name="foot_to_foundation" type="fixed">
        <parent link="foot" />
        <child link="foundation" />
        <origin rpy="0 0 0" xyz="0 0 0.15" />
    </joint>

    <link name="foundation">
        <visual>
            <geometry>
                <!-- x-red, y-green, z-blue -->
                <box size="${foundation_width}
                           ${foundation_depth}
                           ${foundation_height}" />
            </geometry>
            <origin rpy="0 0 0" xyz="0 0 ${foot_height}" />
            <material name="blue">
                <color rgba="0 0 1 1" />
            </material>
        </visual>
        <collision>
            <geometry>
                <box size="${foundation_width}
                           ${foundation_depth}
                           ${foundation_height}" />
            </geometry>
            <origin rpy="0 0 0" xyz="0 0 ${foot_height}" />
        </collision>
        <xacro:inertial_matrix
            mass="${foundation_mass}"
            x_length="${foundation_width}"
            y_length="${foundation_depth}"
            z_length="${foundation_height}"
            />
    </link>

    <joint name="foundation_to_connector" type="prismatic">
        <parent link="foundation" />
        <child link="connector" />
        <origin rpy="0 0 0" xyz="0 0 1.2" />
        <limit upper="1.80" lower="-1.80" effort="100" velocity="100" />
        <axis xyz="0 1 0" />
    </joint>

    <link name="connector">
        <visual>
            <geometry>
                <box size="${connector_width}
                           ${connector_depth}
                           ${connector_height}" />
            </geometry>
            <origin rpy="0 0 0" xyz="0 0 0" />
            <material name="yellow">
                <color rgba="1 1 0 1" />
            </material>
        </visual>
        <collision>
            <geometry>
                <box size="${connector_width}
                           ${connector_depth}
                           ${connector_height}" />
            </geometry>
            <origin rpy="0 0 0" xyz="0 0 0" />
        </collision>
        <xacro:inertial_matrix
            mass="${connector_mass}"
            x_length="${connector_width}"
            y_length="${connector_depth}"
            z_length="${connector_height}" />
    </link>

    <joint name="connector_to_arm" type="revolute">
        <parent link="connector" />
        <child link="arm" />
        <origin rpy="0 0 0" xyz="0 0 0.2" />
        <limit upper="${3.14/2}" lower="${-3.14/2}"
            effort="100" velocity="100" />
        <axis xyz="1 0 0" />
        <!-- Determine how these are calculated! -->
        <dynamics damping="0.5" friction="0.2" />
    </joint>

    <link name="arm">
        <visual>
            <geometry>
                <box size="${arm_width}
                           ${arm_depth}
                           ${arm_height}" />
            </geometry>
            <origin rpy="0 0 0" xyz="0 0 1.3" />
            <material name="green">
                <color rgba="0 1 0 1" />
            </material>
        </visual>
        <collision>
            <geometry>
                <box size="${arm_width}
                           ${arm_depth}
                           ${arm_height}" />
            </geometry>
            <origin rpy="0 0 0" xyz="0 0 1.3" />
        </collision>
        <xacro:inertial_matrix2
            mass="${arm_mass}"
            x_length="${arm_width}"
            y_length="${arm_depth}"
            z_length="${arm_height}" />
    </link>

    <joint name="arm_to_imu" type="fixed">
        <parent link="arm" />
        <child link="imu_link" />
        <origin rpy="0 0 0" xyz="0 0 0" />
        <axis xyz="0 0 0" rpy="0 0 0" />
    </joint>

    <link name="imu_link">
        <visual>
            <geometry>
                <box size="0.2 0.2 0.2" />
            </geometry>
            <origin rpy="0 0 0" xyz="0 0 2.7" />
            <material name="gray">
                <color rgba="0.5 0.5 0.5 1" />
            </material>
        </visual>
    </link>

    <!-- transmissions -->
    <xacro:transmission_block joint_name="foundation_to_connector" />
    <xacro:transmission_block joint_name="connector_to_arm" />

    <gazebo reference="imu_link">
        <gravity>true</gravity>
        <sensor name="imu_sensor" type="imu">
            <alwaysOn>true</alwaysOn>
            <update_rate>100</update_rate>
            <visualize>true</visualize>
            <topic>__default_topic__</topic>
            <plugin filename="libgazebo_ros_imu_sensor.so" name="imu_plugin">
                <topicName>imu</topicName>
                <bodyName>imu_link</bodyName>
                <updateRateHZ>10.0</updateRateHZ>
                <gaussianNoise>0.0</gaussianNoise>
                <xyzOffset>0 0 0</xyzOffset>
                <rpyOffset>0 0 0</rpyOffset>
                <frameName>imu_link</frameName>
                <initialOrientationAsReference>false</initialOrientationAsReference>
            </plugin>
            <pose>0 0 0 0 0 0</pose>
        </sensor>
    </gazebo>

</robot>

