<?xml version="1.0" ?>
<!-- =================================================================================== -->
<!-- |    This document was autogenerated by xacro from ./inverse_pendulum.xacro       | -->
<!-- |    EDITING THIS FILE BY HAND IS NOT RECOMMENDED                                 | -->
<!-- =================================================================================== -->
<robot name="inverse_pendulum" xmlns:xacro="http://www.ros.org/wiki/xacro">
  <link name="base">
    <visual>
      <geometry>
        <box size="4 4 0.1"/>
      </geometry>
      <origin rpy="0 0 0" xyz="0 0 0"/>
    </visual>
  </link>
  <joint name="base_to_foundation" type="fixed">
    <parent link="base"/>
    <child link="foundation"/>
    <origin rpy="0 0 0" xyz="0 0 0"/>
  </joint>
  <link name="foundation">
    <visual>
      <geometry>
        <box size="0.5 4 1.0"/>
      </geometry>
      <origin rpy="0 0 0" xyz="0 0 0.6"/>
      <material name="blue">
        <color rgba="0 0 1 1"/>
      </material>
    </visual>
    <collision>
      <geometry>
        <box size="0.5 4 1.0"/>
      </geometry>
      <origin rpy="0 0 0" xyz="0 0 0.6"/>
    </collision>
    <inertial>
      <mass value="1"/>
      <inertia ixx="0.5" ixy="0.0" ixz="0.0" iyy="0.5" iyz="0.0" izz="0.5"/>
    </inertial>
  </link>
  <joint name="foundation_to_connector" type="prismatic">
    <parent link="foundation"/>
    <child link="connector"/>
    <origin rpy="0 0 0" xyz="0 0 1.2"/>
    <limit effort="100" lower="-1.80" upper="1.80" velocity="100"/>
    <axis xyz="0 1 0"/>
  </joint>
  <link name="connector">
    <visual>
      <geometry>
        <box size="0.2 0.2 0.2"/>
      </geometry>
      <origin rpy="0 0 0" xyz="0 0 0"/>
      <material name="yellow">
        <color rgba="1 1 0 1"/>
      </material>
    </visual>
    <collision>
      <!-- TODO: Tune this to more realistic values -->
      <geometry>
        <box size="0.2 0.2 0.2"/>
      </geometry>
      <origin rpy="0 0 0" xyz="0 0 0"/>
    </collision>
    <inertial>
      <mass value="1"/>
      <inertia ixx="0.5" ixy="0.0" ixz="0.0" iyy="0.5" iyz="0.0" izz="0.5"/>
    </inertial>
  </link>
  <joint name="connector_to_arm" type="revolute">
    <parent link="connector"/>
    <child link="arm"/>
    <origin rpy="-1.57 0 0" xyz="0 0 0.2"/>
    <limit effort="100" lower="0" upper="3.14" velocity="100"/>
    <axis xyz="1 0 0"/>
  </joint>
  <link name="arm">
    <visual>
      <geometry>
        <box size="0.2 0.2 2.5"/>
      </geometry>
      <origin rpy="0 0 0" xyz="0 0 1.3"/>
      <material name="green">
        <color rgba="0 1 0 1"/>
      </material>
    </visual>
    <collision>
      <geometry>
        <box size="0.2 0.2 2.5"/>
      </geometry>
      <origin rpy="0 0 0" xyz="0 0 1.3"/>
    </collision>
    <inertial>
      <mass value="5"/>
      <inertia ixx="0.5" ixy="0.0" ixz="0.0" iyy="0.5" iyz="0.0" izz="0.5"/>
    </inertial>
  </link>
</robot>
